Workbook

Sheet Proposal Form Tier 1
A1: Specific Criteria For the quote | B1: Quantity | E1: Instructions
A2: End-User Name | B2: Bank of America
A3: Number Of Controllers | B3: 9
C4: Chosen Tier Min QTY of Controllers | D4: Chosen Tier Max QTY of Controllers
A5: Annual Service Tier Level | B5: =_xlfn.XLOOKUP($B$3,Tiers_list!$D:$D,Tiers_list!$A:$A,,1) -> Tier - 1 - 10 | C5: =_xlfn.XLOOKUP('Proposal Form Tier 1'!$B$5,Tiers_list!$A:$A,Tiers_list!C:C,,0) -> 1 | D5: =_xlfn.XLOOKUP('Proposal Form Tier 1'!$B$5,Tiers_list!$A:$A,Tiers_list!D:D,,0) -> 10 | E5: =IF(B5<>"Tier - 1 - 10","This Sheet is intended for Tier 1. If controller over 10 use 'Basic Form Tier 2-12'","")
A6: Quantity of Annual Primary Production Instance(s) | B6: 1
A8: Quantity of Annual Primary Fail-Over Instance(s) | B8: 0
A9: Quantity of Annual DR Instance(s) | B9: 0
A10: Quantity of Annual DR Failover Instance(s) | B10: 1
A11: Total Quantity of Annual Fail-Over / DR Instance(s) | B11: =SUM(B8:B10) -> 1
A12: Percentage of Production cost to use for Failover and DR Instance(s) | B12: 0.5
A14: End-User Discount Rate | B14: =_xlfn.XLOOKUP(B2,End_user!A:A,End_user!B:B,0,0) -> 0
A15: Integrator Name | B15: Securitas Technology Co.
A16: Integrator Discount Rate | B16: =_xlfn.XLOOKUP(B15,'Integrator List'!A:A,'Integrator List'!B:B,0,0) -> 0.25
A19: Annual - Advanced Optional Micro Services | B19: Quantity | C19: Product Number | D19: UOM
A20: =_xlfn.XLOOKUP($C20,Tiers_list!$2:$2,Tiers_list!$1:$1,,0) -> ACS system data non cloud integration / parser to 3rd party systems ACS Event Messages, Credentials and User Logs Module | B20: 1 | C20: 200-50048 | D20: ea. | E20: Annual
A21: =_xlfn.XLOOKUP($C21,Tiers_list!$2:$2,Tiers_list!$1:$1,,0) -> ACS Job Scheduler Service Module | B21: 1 | C21: 200-50059 | D21: ea. | E21: Annual
A22: =_xlfn.XLOOKUP($C22,Tiers_list!$2:$2,Tiers_list!$1:$1,,0) -> AFH / Data Collection Service Module | B22: 1 | C22: 200-50060 | D22: ea. | E22: Annual
A23: =_xlfn.XLOOKUP($C23,Tiers_list!$2:$2,Tiers_list!$1:$1,,0) -> Remote ACS Hardware firmware updates Module | B23: 1 | C23: 200-50061 | D23: ea. | E23: Annual
A24: =_xlfn.XLOOKUP($C24,Tiers_list!$2:$2,Tiers_list!$1:$1,,0) -> Reader Credentials Accepted and Rejected Supervision Module | B24: 1 | C24: 200-50069 | D24: ea. | E24: Annual
A26: =_xlfn.XLOOKUP($C26,Tiers_list!$2:$2,Tiers_list!$1:$1,,0) -> ACS TLS 1.2/1.3 PCB | B26: =+B3 -> 9 | C26: 200-50070 | D26: ea. | E26: Annual
A27: =_xlfn.XLOOKUP($C27,Tiers_list!$2:$2,Tiers_list!$1:$1,,0) -> 24/7 ACS Enterprise Telephone Support | B27: 1 | C27: YEAR-ACS-RTS | D27: ea. | E27: Annual / Optional
A28: =_xlfn.XLOOKUP($C28,Tiers_list!$2:$2,Tiers_list!$1:$1,,0) -> Annual Remote Training ACS | B28: 1 | C28: 1000-30054 | D28: Required. Choose Qty of 10 hours slots | E28: Annual
A30: =_xlfn.XLOOKUP($C30,Tiers_list!$2:$2,Tiers_list!$1:$1,,0) -> ACS Enterprise - Tech Software License - Annual Software Assurance | B30: 0 | C30: 200-50007-NTS | D30: ea. | E30: Annual
A32: One-Time Required Hardware and Installation Service and support | B32: Quantity | C32: =+C19 -> Product Number | D32: UOM
A33: =_xlfn.XLOOKUP($C33,Tiers_list!$2:$2,Tiers_list!$1:$1,,0) -> TLS 1.2/1.3 PCB | B33: =+B26 -> 9 | C33: 200-10115-PCBA | D33: ea. | E33: One-Time
A34: =_xlfn.XLOOKUP($C34,Tiers_list!$2:$2,Tiers_list!$1:$1,,0) -> ACS Enterprise - Hardware - Controller Firmware Programmer KIT - No license Provided. | B34: 0 | C34: 200-50007-KT | D34: ea. | E34: One-Time
A36: Trip Charge | B36: =+IF(B15="Parabit Systems,Inc.",B3,0) -> 0 | C36: 1000-30052 | D36: ea. | E36: One-Time if Parabit is the Installer
A37: On-Site/Remote Low Voltage/Mechanical Tech Weekday Business Hours | B37: =+B36*2 -> 0 | C37: 1000-20000 | D37: ea. | E37: One-Time if Parabit is the Installer
A38: Project Management | B38: =0.15*B36 -> 0 | C38: 1000-30045 | D38: ea. | E38: One-Time if Parabit is the Installer
A40: Annual Optional Software | B40: Quantity | C40: =+C32 -> Product Number | D40: UOM | E40: Quantity chosen here will appear in Detail Software Sheet (light blue cells)
A41: =_xlfn.XLOOKUP($C41,Tiers_list!$2:$2,Tiers_list!$1:$1,,0) -> Controller/Reader Credential Enrollment Management Module | B41: 0 | C41: 200-50043 | D41: ea.
A42: =_xlfn.XLOOKUP($C42,Tiers_list!$2:$2,Tiers_list!$1:$1,,0) -> ACS system data cloud integration to 3rd party systems ACS Event Messages, Credentials and User Logs Module | B42: 0 | C42: 200-50047 | D42: ea.
A43: =_xlfn.XLOOKUP($C43,Tiers_list!$2:$2,Tiers_list!$1:$1,,0) -> Email/Text EMR Notifier Service Module | B43: 0 | C43: 200-50049 | D43: ea.
A44: =_xlfn.XLOOKUP($C44,Tiers_list!$2:$2,Tiers_list!$1:$1,,0) -> ACS controller Reader Remote Credential Lookup with Local learn Module | B44: 0 | C44: 200-50050 | D44: ea.
A45: =_xlfn.XLOOKUP($C45,Tiers_list!$2:$2,Tiers_list!$1:$1,,0) -> HR & Time Attendance Credential Integration Module | B45: 0 | C45: 200-50053 | D45: ea.
A46: =_xlfn.XLOOKUP($C46,Tiers_list!$2:$2,Tiers_list!$1:$1,,0) -> ACS Hardware and Facility Sensor Data Integration(s) Module | B46: 0 | C46: 200-50054 | D46: ea.
A47: =_xlfn.XLOOKUP($C47,Tiers_list!$2:$2,Tiers_list!$1:$1,,0) -> Suspend distribution of Select or All Event Messages generated by ACS hardware and software Module | B47: 0 | C47: 200-50058 | D47: ea.
A48: =_xlfn.XLOOKUP($C48,Tiers_list!$2:$2,Tiers_list!$1:$1,,0) -> Door / Entrance Supervision Configuration Module | B48: 0 | C48: 200-50062 | D48: ea.
A49: =_xlfn.XLOOKUP($C49,Tiers_list!$2:$2,Tiers_list!$1:$1,,0) -> ACS Controller Software Integrations DB Ecosystem Supervision Module | B49: 0 | C49: 200-50068 | D49: ea.
...

Sheet Detail_Proposal_tier 1
A1: Product # | B1: Product Tree | C1: Category | D1: Prod # Description | E1: Feature Description | F1: Business Description | G1: Feature Type | H1: UoM | I1: =CONCATENATE('Proposal Form Tier 1'!B5," ","Quantity of Primary Production Instance(s)") -> Tier - 1 - 10 Quantity of Primary Production Instance(s) | J1: =CONCATENATE('Proposal Form Tier 1'!B5," ","Total Annual Primary Instance(s) Pricing") -> Tier - 1 - 10 Total Annual Primary Instance(s) Pricing | K1: =CONCATENATE('Proposal Form Tier 1'!B5," ","Total Annual Fail-Over/DR Instance(s) Pricing") -> Tier - 1 - 10 Total Annual Fail-Over/DR Instance(s) Pricing | L1: =CONCATENATE('Proposal Form Tier 1'!B5," ","Total Quantity of Annual Fail-Over/DR Instance(s)") -> Tier - 1 - 10 Total Quantity of Annual Fail-Over/DR Instance(s) | M1: Enter # of Instances per Tier - Quantity of Annual Primary Fail-Over Instance(s) | N1: Enter # of Instances per Tier - Quantity of DR Instance(s) | O1: Enter # of Instances per Tier - Quantity of DR Failover Instance(s) | P1: MSRP / Tier Price Primary Production Instances
A2: 200-50042 | B2: ACS Software | C2: ACS Enterprise Hardware Configuration UI | D2: =_xlfn.XLOOKUP(A2,Tiers_list!$2:$2,Tiers_list!$1:$1,,0) -> Campus, Site, Floor, Controller, Entrance/Reader, User, Credential, Configuration, Diagnostics and Reports Module | E2: By Site by ACS Controller Customer defined ID, Digital Serial #, Customer defined asset tag, Entrance location data (Address, Cross Streets, Contact, Phone, Email, etc., Time Zone/DST, I/O configuration, Overlay/RFID Skim Detection times, IP/Port, DNS, DHCP. By Reader/Entrance: Reader Serial #, PID, Weekly and Holiday schedule(s) assignment, Digital API Data Integration(s) settings, Entrance Door Release duration, Door Ajar detect time, Door opening excessively to Credentials read ratio, Customer Can't Enter/Exit sequential configuration, Reader Egress time, Exit/Entry Switch Egress time, Anti-Tailgating Active/Disabled, Physical Overlay/RFID Skimmer Detect Time, Reader and Lock state Inhibit Active/Disabled integration, Loitering, Single Access, Light Sensor, Last ATM Transaction Date/Time and 3rd party system configurations. | F2: ACS Cloud Enterprise gives operators and administrators a single, unified interface to configure every layer of their access control environment — from site addresses, time zones, and network settings down to individual reader behaviors, credential masks, and third-party integration parameters. Rather than juggling separate tools or on-site visits, teams can define and push the complete hardware profile of every controller and entrance from the cloud, ensuring every site is consistently configured, operationally ready, and aligned with organizational standards from day one. | G2: Required | H2: ea. | I2: =IF('Proposal Form Tier 1'!$B$5=Tiers_list!$A$3,+'Proposal Form Tier 1'!B6,1) -> 1 | J2: =VLOOKUP('Proposal Form Tier 1'!$B$5,Tiers_list!$A:$BC,MATCH($A2,Tiers_list!$2:$2,0),FALSE)*('Proposal Form Tier 1'!$B$3/10)*(1-'Proposal Form Tier 1'!B14-'Proposal Form Tier 1'!B16) -> 2025 | K2: =J2*50% -> 1012.5 | L2: =SUM(M2:O2) -> 1 | M2: =IF($I2>0,+'Proposal Form Tier 1'!$B$8,0) -> 0 | N2: =IF($I2>0,+'Proposal Form Tier 1'!$B$9,0) -> 0 | O2: =IF($I2>0,+'Proposal Form Tier 1'!$B$10,0) -> 1 | P2: =+(J2/(1-'Proposal Form Tier 1'!$B$16-'Proposal Form Tier 1'!$B$14))+(K2/(1-'Proposal Form Tier 1'!$B$16-'Proposal Form Tier 1'!$B$14)) -> 4050
B3: ACS Software | C3: ACS Enterprise Hardware Configuration UI | D3: Campus, Site, Floor, Controller, Entrance/Reader, User, Credential, Configuration, Diagnostics and Reports Module | E3: Create/edit/update/deactivate ACS Users and ACS Users who assign access rights to ACS features | F3: Administrators gain full lifecycle control over every system user — creating, editing, and deactivating accounts while assigning precise role-based access rights that determine exactly which ACS features and data each person can reach. By tying permissions directly to user profiles rather than managing them ad hoc, organizations eliminate over-privileged accounts, enforce the principle of least privilege, and maintain a clean, auditable record of who has access to what across the entire platform.
B4: ACS Software | C4: ACS Enterprise Hardware Configuration UI | D4: Campus, Site, Floor, Controller, Entrance/Reader, User, Credential, Configuration, Diagnostics and Reports Module | E4: Active Directory (AD) support | F4: For organizations already running Microsoft Active Directory, ACS Cloud Enterprise eliminates the need for a separate set of user credentials by enabling staff to log in using their existing AD accounts. Operators can search, assign, and manage AD users and groups directly within ACS — with access permissions updating automatically in real time whenever an AD account is modified or disabled — reducing administrative burden and closing the security gaps that come from manually maintained duplicate user lists.
B5: ACS Software | C5: ACS Enterprise Hardware Configuration UI | D5: Campus, Site, Floor, Controller, Entrance/Reader, User, Credential, Configuration, Diagnostics and Reports Module | E5: Configure reader type, access by Credential holder and by Access Schedule for MMR 2.0 reader Mag Stripe and NFC Card. | F5: Operators can configure every reader in the system — defining the credential types accepted (magnetic stripe, NFC, Bluetooth, biometric, and more), assigning the appropriate access schedules, and linking readers to specific user groups — all from a centralized interface without a site visit. This ensures that every entrance behaves exactly as intended, that the right people have access at the right times, and that configuration changes are applied instantly and consistently across all locations.
B6: ACS Software | C6: ACS Enterprise Hardware Configuration UI | D6: Campus, Site, Floor, Controller, Entrance/Reader, User, Credential, Configuration, Diagnostics and Reports Module | E6: Configure Readers and/or Users on type of credential(s) required to access an entrance or group of entrances. i.e., a reader can require one, two or more types of credentials by Reader or User to gain access to a (or group of) specified Reader. | F6: Organizations can define precise credential matching rules for each reader or entrance — specifying exactly which credential types, card formats, and validation methods are required to gain access at any given point. Whether using standard match, bank credential fallback, external match validation, or protocol-based NFC matching, operators can tailor access logic per reader without firmware changes, giving security teams granular control over who gets through each door and under what conditions.
B7: ACS Software | C7: ACS Enterprise Hardware Configuration UI | D7: Campus, Site, Floor, Controller, Entrance/Reader, User, Credential, Configuration, Diagnostics and Reports Module | E7: Remote ACS controller I/O test and status inquiry | F7: Field technicians and operators can remotely test and query the real-time status of any ACS controller's I/O channels without traveling to the site, enabling rapid diagnosis of hardware issues, connection faults, and configuration mismatches from the cloud. This reduces costly site visits, shortens mean time to resolution, and ensures that technical teams have full visibility into device health before deploying maintenance resources.
B8: ACS Software | C8: ACS Enterprise Hardware Configuration UI | D8: Campus, Site, Floor, Controller, Entrance/Reader, User, Credential, Configuration, Diagnostics and Reports Module | E8: Define and remotely configure Weekly Access Schedule (Credentials required), Open (entrance unlocked) and Locked (entrance closed) | F8: Operators can define weekly access schedules — specifying which credential is required, when an entrance is open to all, or when it is locked — and push those schedules remotely to any controller or group of controllers across the organization. This eliminates manual on-site programming for routine schedule updates, ensures schedules are applied consistently across all sites, and gives security teams the flexibility to respond to operational changes without delay.
B9: ACS Software | C9: ACS Enterprise Hardware Configuration UI | D9: Campus, Site, Floor, Controller, Entrance/Reader, User, Credential, Configuration, Diagnostics and Reports Module | E9: Define Annual Holiday Access (Credential required), Open (entrance unlocked) and Locked (entrance closed) schedule. Notify selected ACS users when a future defined holiday date and schedule has not been defined within the ACS database or programmed into the ACS controller | F9: Define Annual Holiday Access (Credential required), Open (entrance unlocked) and Locked (entrance closed) schedule. Notify selected ACS users when a future defined holiday date and schedule has not been defined within the ACS database or programmed into the ACS controller
B10: ACS Software | C10: ACS Enterprise Hardware Configuration UI | D10: Campus, Site, Floor, Controller, Entrance/Reader, User, Credential, Configuration, Diagnostics and Reports Module | E10: Manage and remotely configure credentials table/configuration accepted for NFC, Magnetic Stripe. Accepted Credentials, Admin Credentials, Financial Credential types and Exception tables and assign to reader(s)/entrance(s). | F10: Operators can create, import, edit, merge, and export credential lists — covering accepted credentials, administrative cards, financial credential types, and exception (suspect/reject) tables — and assign them directly to individual readers or push them across multiple sites simultaneously. By centralizing credential list management in the cloud, organizations avoid the risks of outdated lists on individual controllers and ensure that access decisions are always based on the most current and accurate credential data available.
B11: ACS Software | C11: ACS Enterprise Hardware Configuration UI | D11: Campus, Site, Floor, Controller, Entrance/Reader, User, Credential, Configuration, Diagnostics and Reports Module | E11: Remotely set an ACS controllers Maintenance Mode (Active/Clear) | F11: Operators and technicians can remotely activate and manage Maintenance Mode on any ACS controller, flagging all activity during that window so that alarms generated by maintenance work are clearly identified and not mistakenly escalated to monitoring centers. With configurable durations, automatic expiry, and real-time event tracking of who activated maintenance, when, and for how long, organizations maintain full operational accountability even during planned downtime.
B12: ACS Software | C12: ACS Enterprise Hardware Configuration UI | D12: Campus, Site, Floor, Controller, Entrance/Reader, User, Credential, Configuration, Diagnostics and Reports Module | E12: Remote Door/Entrance Unlock for x - xx seconds | F12: Administrators and operators can instantly unlock any entrance remotely for a defined duration — whether responding to an emergency, assisting a visitor, or supporting a maintenance request — without sending a technician to the site. The action is logged in the audit trail, automatically reversed after the configured time, and fully visible in real-time event monitoring, giving teams both the speed to respond and the traceability to stay compliant.
B13: ACS Software | C13: ACS Enterprise Hardware Configuration UI | D13: Campus, Site, Floor, Controller, Entrance/Reader, User, Credential, Configuration, Diagnostics and Reports Module | E13: Remote Door/Entrance Access Schedule State Override with an until date/time (Access, Lock or Open). | F13: When circumstances require a door to behave differently from its standard schedule — planned maintenance, emergency access, special events, or adverse weather — operators can remotely override the entrance state (open, access, or locked) for a defined date and time window without modifying the underlying schedule. The override clears automatically when the window expires, the original schedule resumes immediately, and the entire action is logged, ensuring operational flexibility never comes at the cost of security accountability.
B14: ACS Software | C14: ACS Enterprise Hardware Configuration UI | D14: Campus, Site, Floor, Controller, Entrance/Reader, User, Credential, Configuration, Diagnostics and Reports Module | E14: Manage User Access Credential(s) data: Import/Export .csv files • Credential Type: Bio Datapoint file1, Bio Datapoint file2, Bio Datapoint file…, Keypad Code, Mobile Device EIN/MAC???, etc. • Prox/NFC Card or Bluetooth: Facility Code / BIN number or ID / PAN number • 5 fields for 1st, middle, last, etc. names • ID used to validate Credential Holder • Driver’s License, Passport, Social Security #, Employee ID #, User Defined Credential 1, User Defined Credential 2… • Address1: #, Street, City, County, Town, Village, Prefecture, State, Zip/Postal Code, Country, • Address2: #, Street, City, County, Town, Village, Prefecture, State, Zip/Postal Code, Country, • Phone1, Phone2, etc. • Email1, Email2, etc. • Manager1, Phone1, Email1 • Manager2, Phone1, Email1 • (Investigate other credential types / fields required per credential and type): | F14: Operators can manage the full credential data profile for each user — importing and exporting credential records via CSV, defining credential types accepted per user, and linking physical or virtual credentials to access rights — giving organizations a clean, importable, and auditable record of who holds which credential and what they can access. This streamlines onboarding, offboarding, and credential audits while reducing the manual effort and error risk of maintaining credential records outside the system.
B15: ACS Software | C15: ACS Enterprise Hardware Configuration UI | D15: Campus, Site, Floor, Controller, Entrance/Reader, User, Credential, Configuration, Diagnostics and Reports Module | E15: View, export and reports sites, hardware, configuration, events, credentials read, user functions executed, user/hardware configuration change logs and ACS controller and reader inventory | F15: Administrators, operators, and auditors can view, filter, search a comprehensive set of reports spanning site activity, hardware status, configuration changes, credential events, and user actions — all from a single interface. Whether preparing for a compliance audit, investigating a security incident, or reviewing operational performance, teams can generate the exact data they need in seconds.
A16: 200-50043 | B16: ACS Software | C16: ACS Enterprise Hardware Configuration UI | D16: =_xlfn.XLOOKUP(A16,Tiers_list!$2:$2,Tiers_list!$1:$1,,0) -> Controller/Reader Credential Enrollment Management Module | E16: Configure an ACS controller reader to learn/enroll a credential. The learn/enroll feature is configured by one or more designated User approval(s). | F16: ACS Cloud Enterprise enables any configured reader to enter a learn or enrollment mode, automatically capturing and storing a new credential when it is presented — eliminating the need to manually enter card numbers during onboarding. This accelerates the setup of new cardholders at large-scale deployments, reduces data entry errors, and gives operators a fast, reliable way to add credentials to the system directly from the physical reader. | G16: Optional | H16: ea. | I16: =_xlfn.XLOOKUP($A16,'Proposal Form Tier 1'!$C:$C,'Proposal Form Tier 1'!$B:$B,0,0) -> 0 | J16: =VLOOKUP('Proposal Form Tier 1'!$B$5,Tiers_list!$A:$BC,MATCH($A16,Tiers_list!$2:$2,0),FALSE)*(I16/10)*(1-'Proposal Form Tier 1'!$B$16-'Proposal Form Tier 1'!$B$14) -> 0 | K16: =J16*50% -> 0 | L16: =SUM(M16:O16) -> 0 | P16: =+(J16/(1-'Proposal Form Tier 1'!$B$16-'Proposal Form Tier 1'!$B$14))+(K16/(1-'Proposal Form Tier 1'!$B$16-'Proposal Form Tier 1'!$B$14)) -> 0
A17: 200-50044 | B17: ACS Software | C17: ACS Enterprise Hardware Configuration UI | D17: =_xlfn.XLOOKUP(A17,Tiers_list!$2:$2,Tiers_list!$1:$1,,0) -> ACS User Login Profile Management Module | E17: Create/Edit/Deactivate ACS Users and assign ACS User function/data access rights by ACS User/ACS User Profile type (Super Admin, Admin, Super Investigator, Investigator, Super Production user, Production user, etc.) A user profile is a type of user(s) that has been defined to perform specified functions within the ACS Enterprise software suite. | F17: Administrators can create, edit, and deactivate ACS user accounts and assign each user precise function and data access rights that determine which modules, sites, and operations they can perform within the platform. With role-based permissions, automated lockout on permission changes, and a full audit trail of every modification, organizations maintain tight control over who can administer the system and ensure that access rights always reflect current responsibilities. | G17: Required | H17: ea. | I17: =+'Proposal Form Tier 1'!$B$6 -> 1 | J17: =VLOOKUP('Proposal Form Tier 1'!$B$5,Tiers_list!$A:$BC,MATCH($A17,Tiers_list!$2:$2,0),FALSE)*('Proposal Form Tier 1'!B3/10)*(1-'Proposal Form Tier 1'!$B$16-'Proposal Form Tier 1'!$B$14) -> 126.5625 | K17: =J17*50% -> 63.28125 | L17: =SUM(M17:O17) -> 1 | M17: =IF($I17>0,+'Proposal Form Tier 1'!$B$8,0) -> 0 | N17: =IF($I17>0,+'Proposal Form Tier 1'!$B$9,0) -> 0 | O17: =IF($I17>0,+'Proposal Form Tier 1'!$B$10,0) -> 1 | P17: =+(J17/(1-'Proposal Form Tier 1'!$B$16-'Proposal Form Tier 1'!$B$14))+(K17/(1-'Proposal Form Tier 1'!$B$16-'Proposal Form Tier 1'!$B$14)) -> 253.125
A18: 200-50045 | B18: ACS Software | C18: ACS Enterprise Hardware Configuration UI | D18: =_xlfn.XLOOKUP(A18,Tiers_list!$2:$2,Tiers_list!$1:$1,,0) -> ACS Controller / User Territory Management Module | E18: Manage Territory's by geographic region, state, time zone, defined controller properties and/or by User. Assign ACS controllers to a Territory(s) and assign Territory(s) to an ACS User(s) supporting assignment of ACS functions to be executed/managed. | G18: Required | H18: ea. | I18: =+'Proposal Form Tier 1'!$B$6 -> 1 | J18: =VLOOKUP('Proposal Form Tier 1'!$B$5,Tiers_list!$A:$BC,MATCH($A18,Tiers_list!$2:$2,0),FALSE)*('Proposal Form Tier 1'!B3/10)*(1-'Proposal Form Tier 1'!$B$16-'Proposal Form Tier 1'!$B$14) -> 126.5625 | K18: =J18*50% -> 63.28125 | L18: =SUM(M18:O18) -> 1 | M18: =IF($I18>0,+'Proposal Form Tier 1'!$B$8,0) -> 0 | N18: =IF($I18>0,+'Proposal Form Tier 1'!$B$9,0) -> 0 | O18: =IF($I18>0,+'Proposal Form Tier 1'!$B$10,0) -> 1 | P18: =+(J18/(1-'Proposal Form Tier 1'!$B$16-'Proposal Form Tier 1'!$B$14))+(K18/(1-'Proposal Form Tier 1'!$B$16-'Proposal Form Tier 1'!$B$14)) -> 253.125
C19: ACS Enterprise Hardware Configuration UI Total | I19: =SUBTOTAL(9,I2:I18) -> 3 | J19: =SUBTOTAL(9,J2:J18) -> 2278.125 | K19: =SUBTOTAL(9,K2:K18) -> 1139.0625 | L19: =SUBTOTAL(9,L2:L18) -> 3 | M19: =SUBTOTAL(9,M2:M18) -> 0 | N19: =SUBTOTAL(9,N2:N18) -> 0 | O19: =SUBTOTAL(9,O2:O18) -> 3 | P19: =SUBTOTAL(9,P2:P18) -> 4556.25
A20: 200-50046 | B20: ACS Software | C20: ACS Enterprise Integrations | D20: =_xlfn.XLOOKUP(A20,Tiers_list!$2:$2,Tiers_list!$1:$1,,0) -> Integration to External ACS Hardware / Software Certificate / Key software / system Module | E20: ACS controller and MMR 2.0 reader and ACS controller and ACS Enterprise software TLS Communication and Data Encryption External System scheduled or on-demand key/cert generation and management (One-Time and Annual Pricing TBD) | F20: ACS Cloud Enterprise secures all communications between controllers, Readers and the cloud using mutual TLS — which is the strongest encryption. This ensures credential data, control commands, and event messages are protected against interception and replay attacks. Certificates are stored in cloud key vaults with policy-controlled access and automated rotation, and all authentication activity is logged, giving organizations the cryptographic foundation needed to meet demanding security and compliance requirements. | G20: Required | H20: ea. | I20: =+'Proposal Form Tier 1'!$B$6 -> 1 | J20: =VLOOKUP('Proposal Form Tier 1'!$B$5,Tiers_list!$A:$BC,MATCH($A20,Tiers_list!$2:$2,0),FALSE)*('Proposal Form Tier 1'!B3/10)*(1-'Proposal Form Tier 1'!$B$16-'Proposal Form Tier 1'!$B$14) -> 168.75 | K20: =J20*50% -> 84.375 | L20: =SUM(M20:O20) -> 1 | M20: =IF($I20>0,+'Proposal Form Tier 1'!$B$8,0) -> 0 | N20: =IF($I20>0,+'Proposal Form Tier 1'!$B$9,0) -> 0 | O20: =IF($I20>0,+'Proposal Form Tier 1'!$B$10,0) -> 1 | P20: =+(J20/(1-'Proposal Form Tier 1'!$B$16-'Proposal Form Tier 1'!$B$14))+(K20/(1-'Proposal Form Tier 1'!$B$16-'Proposal Form Tier 1'!$B$14)) -> 337.5
A21: 200-50047 | B21: ACS Software | C21: ACS Enterprise Integrations | D21: =_xlfn.XLOOKUP(A21,Tiers_list!$2:$2,Tiers_list!$1:$1,,0) -> ACS system data cloud integration to 3rd party systems ACS Event Messages, Credentials and User Logs Module | E21: Define, Parse and forward ACS Event Messages collected/received by ACS controllers via a API / Windows / Micro Service to 3rd party alarm/event message monitoring systems in the following (ContactID, Extended Contact ID, others TBD) formats (MAStermind supported today, but develop interfaces to Genetec, MAStermind, Milestone, Avigilon and others.) | F21: ACS Cloud Enterprise collects, parses, and categorizes every event message generated by ACS controllers — including credential reads, door events, alarms, health checks, and system actions — and routes them to the appropriate destinations in real time. Operators can configure exactly which message types are forwarded to internal databases, external monitoring platforms, or third-party systems, with full control over message priority, credential data masking, and failover queuing to ensure no critical event is lost even when downstream systems are temporarily unavailable. | G21: Optional | H21: ea. | I21: =_xlfn.XLOOKUP($A21,'Proposal Form Tier 1'!$C:$C,'Proposal Form Tier 1'!$B:$B,0,0) -> 0 | J21: =VLOOKUP('Proposal Form Tier 1'!$B$5,Tiers_list!$A:$BC,MATCH($A21,Tiers_list!$2:$2,0),FALSE)*(I21/10)*(1-'Proposal Form Tier 1'!$B$16-'Proposal Form Tier 1'!$B$14) -> 0 | K21: =J21*50% -> 0 | L21: =SUM(M21:O21) -> 0 | P21: =+(J21/(1-'Proposal Form Tier 1'!$B$16-'Proposal Form Tier 1'!$B$14))+(K21/(1-'Proposal Form Tier 1'!$B$16-'Proposal Form Tier 1'!$B$14)) -> 0
A22: 200-50048 | B22: ACS Software | C22: ACS Enterprise Integrations | D22: =_xlfn.XLOOKUP(A22,Tiers_list!$2:$2,Tiers_list!$1:$1,,0) -> ACS system data non cloud integration / parser to 3rd party systems ACS Event Messages, Credentials and User Logs Module | E22: Transmission of ACS Event Messages to non-cloud 3rd party monitoring (MAStermind) applications (Windows Service). (Integration fees may apply) | F22: Organizations using non-cloud monitoring platforms such as MAStermind or similar systems can seamlessly receive ACS event messages through a configurable, authenticated integration that supports multiple server endpoints with automatic failover. Operators define server groups, set message criticality levels, and control credential data exposure in payloads, ensuring that third-party monitoring teams receive exactly the right alerts in real time — without manual intervention and without compromising sensitive cardholder data. | G22: Required. Choose QTY | H22: ea. | I22: =_xlfn.XLOOKUP($A22,'Proposal Form Tier 1'!$C:$C,'Proposal Form Tier 1'!$B:$B,0,0) -> 1 | J22: =IF(I22<>0,VLOOKUP('Proposal Form Tier 1'!$B$5,Tiers_list!$A:$BC,MATCH($A22,Tiers_list!$2:$2,0),FALSE)*('Proposal Form Tier 1'!$B$3/10)*(1-'Proposal Form Tier 1'!$B$16-'Proposal Form Tier 1'!$B$14),0) -> 168.75 | K22: =J22*50% -> 84.375 | L22: =SUM(M22:O22) -> 1 | M22: =IF($I22>0,+'Proposal Form Tier 1'!$B$8,0) -> 0 | N22: =IF($I22>0,+'Proposal Form Tier 1'!$B$9,0) -> 0 | O22: =IF($I22>0,+'Proposal Form Tier 1'!$B$10,0) -> 1 | P22: =+(J22/(1-'Proposal Form Tier 1'!$B$16-'Proposal Form Tier 1'!$B$14))+(K22/(1-'Proposal Form Tier 1'!$B$16-'Proposal Form Tier 1'!$B$14)) -> 337.5
A23: 200-50049 | B23: ACS Software | C23: ACS Enterprise Integrations | D23: =_xlfn.XLOOKUP(A23,Tiers_list!$2:$2,Tiers_list!$1:$1,,0) -> Email/Text EMR Notifier Service Module | E23: EMR sends an email or text to defined Email Address(s)/Mobile #(s) of ACS events selected | F23: Security teams, facility managers, and operations staff can receive instant email or SMS notifications for any ACS event classified as critical — delivered directly to configured user groups without requiring access to the monitoring platform. Operators define notification recipient lists, assign message criticality categories, and configure which alarms trigger immediate outreach, ensuring that the right people are alerted at the right time regardless of whether they are actively monitoring the system dashboard. | G23: Optional | H23: ea. | I23: =_xlfn.XLOOKUP($A23,'Proposal Form Tier 1'!$C:$C,'Proposal Form Tier 1'!$B:$B,0,0) -> 0 | J23: =IF(I23<>0,VLOOKUP('Proposal Form Tier 1'!$B$5,Tiers_list!$A:$BC,MATCH($A23,Tiers_list!$2:$2,0),FALSE)*('Proposal Form Tier 1'!$B$3/10)*(1-'Proposal Form Tier 1'!$B$16-'Proposal Form Tier 1'!$B$14),0) -> 0 | K23: =J23*50% -> 0 | L23: =SUM(M23:O23) -> 0 | P23: =+(J23/(1-'Proposal Form Tier 1'!$B$16-'Proposal Form Tier 1'!$B$14))+(K23/(1-'Proposal Form Tier 1'!$B$16-'Proposal Form Tier 1'!$B$14)) -> 0
A24: 200-50050 | B24: ACS Software | C24: ACS Enterprise Integrations | D24: =_xlfn.XLOOKUP(A24,Tiers_list!$2:$2,Tiers_list!$1:$1,,0) -> ACS controller Reader Remote Credential Lookup with Local learn Module | E24: Remote lookup of Accepted, Rejected and Suspect Credentials in ACS DB. | F24: When a credential is presented at a reader configured for external match validation, ACS Cloud Enterprise forwards the request to the Parabit Cloud Enterprise in real time, retrieves the allow or reject decision, and acts on it immediately . This enables organizations to maintain centralized, organization-wide credential authority in an external system (such as a financial institution's BIN database) while still leveraging the speed and resilience of local controller enforcement. | G24: Optional | H24: ea. | I24: =_xlfn.XLOOKUP($A24,'Proposal Form Tier 1'!$C:$C,'Proposal Form Tier 1'!$B:$B,0,0) -> 0 | J24: =IF(I24<>0,VLOOKUP('Proposal Form Tier 1'!$B$5,Tiers_list!$A:$BC,MATCH($A24,Tiers_list!$2:$2,0),FALSE)*('Proposal Form Tier 1'!$B$3/10)*(1-'Proposal Form Tier 1'!$B$16-'Proposal Form Tier 1'!$B$14),0) -> 0 | K24: =J24*50% -> 0 | L24: =SUM(M24:O24) -> 0 | P24: =+(J24/(1-'Proposal Form Tier 1'!$B$16-'Proposal Form Tier 1'!$B$14))+(K24/(1-'Proposal Form Tier 1'!$B$16-'Proposal Form Tier 1'!$B$14)) -> 0
A25: 200-50051 | B25: ACS Software | C25: ACS Enterprise Integrations | D25: =_xlfn.XLOOKUP(A25,Tiers_list!$2:$2,Tiers_list!$1:$1,,0) -> ACS Enterprise NYCE BIN Table Import / Optimization Module | E25: Monthly download and distribution of the NYCE BIN Table to all ACS Cloud Enterprise Users. Client ACS Cloud Enterprise software detects file update, authenticates and automatically downloads and optimizes the file, then schedules the initialization of the file into all designated ACS controllers. | F25: ACS Cloud Enterprise automates the monthly download and distribution of the NYCE BIN table to all configured controllers across every enterprise site, ensuring that every reader has an up-to-date financial credential reference without requiring manual file transfers or on-site updates. This eliminates the operational risk of controllers running outdated BIN data, reduces the administrative overhead of managing credential table updates at scale, and ensures consistent access decisions across the entire estate. | G25: Required | H25: ea. | I25: =+'Proposal Form Tier 1'!$B$6 -> 1 | J25: =IF(I25<>0,VLOOKUP('Proposal Form Tier 1'!$B$5,Tiers_list!$A:$BC,MATCH($A25,Tiers_list!$2:$2,0),FALSE)*('Proposal Form Tier 1'!$B$3/10)*(1-'Proposal Form Tier 1'!$B$16-'Proposal Form Tier 1'!$B$14),0) -> 126.5625 | K25: =J25*50% -> 63.28125 | L25: =SUM(M25:O25) -> 1 | M25: =IF($I25>0,+'Proposal Form Tier 1'!$B$8,0) -> 0 | N25: =IF($I25>0,+'Proposal Form Tier 1'!$B$9,0) -> 0 | O25: =IF($I25>0,+'Proposal Form Tier 1'!$B$10,0) -> 1 | P25: =+(J25/(1-'Proposal Form Tier 1'!$B$16-'Proposal Form Tier 1'!$B$14))+(K25/(1-'Proposal Form Tier 1'!$B$16-'Proposal Form Tier 1'!$B$14)) -> 253.125
A26: 200-50052 | B26: ACS Software | C26: ACS Enterprise Integrations | D26: =_xlfn.XLOOKUP(A26,Tiers_list!$2:$2,Tiers_list!$1:$1,,0) -> KAL ATM Management Software Integration Module | E26: Remote 6/8 Digit BIN Lookup, Site Lock down and Site Open commands | F26: Operators can execute remote 6- or 8-digit BIN lookup queries against any controller and issue immediate site-wide lockdown or open commands from the cloud — giving security teams the ability to respond to threat events or operational emergencies in seconds without dispatching field personnel. All commands are authenticated, logged, and reversible, ensuring that emergency access control actions are both fast and fully accountable. | G26: Required | H26: ea. | I26: =+'Proposal Form Tier 1'!$B$6 -> 1 | J26: =IF(I26<>0,VLOOKUP('Proposal Form Tier 1'!$B$5,Tiers_list!$A:$BC,MATCH($A26,Tiers_list!$2:$2,0),FALSE)*('Proposal Form Tier 1'!$B$3/10)*(1-'Proposal Form Tier 1'!$B$16-'Proposal Form Tier 1'!$B$14),0) -> 84.375 | K26: =J26*50% -> 42.1875 | L26: =SUM(M26:O26) -> 1 | M26: =IF($I26>0,+'Proposal Form Tier 1'!$B$8,0) -> 0 | N26: =IF($I26>0,+'Proposal Form Tier 1'!$B$9,0) -> 0 | O26: =IF($I26>0,+'Proposal Form Tier 1'!$B$10,0) -> 1 | P26: =+(J26/(1-'Proposal Form Tier 1'!$B$16-'Proposal Form Tier 1'!$B$14))+(K26/(1-'Proposal Form Tier 1'!$B$16-'Proposal Form Tier 1'!$B$14)) -> 168.75
A27: 200-50053 | B27: ACS Software | C27: ACS Enterprise Integrations | D27: =_xlfn.XLOOKUP(A27,Tiers_list!$2:$2,Tiers_list!$1:$1,,0) -> HR & Time Attendance Credential Integration Module | E27: Credential Integration into 3rd Party systems - HR, Time and Attendance, Payroll, Transaction, Credential Management, etc. | F27: ACS Cloud Enterprise can synchronize credential and access event data with external HR, time-and-attendance, payroll, and identity management systems — ensuring that access rights automatically reflect employment status, shift schedules, and organizational changes without requiring duplicate data entry across platforms. This integration eliminates the gaps between physical security and HR processes, reduces the risk of unauthorized access from stale credentials, and provides a unified view of who accessed what and when across interconnected enterprise systems. | G27: Optional | H27: ea. | I27: =_xlfn.XLOOKUP($A27,'Proposal Form Tier 1'!$C:$C,'Proposal Form Tier 1'!$B:$B,0,0) -> 0 | J27: =IF(I27<>0,VLOOKUP('Proposal Form Tier 1'!$B$5,Tiers_list!$A:$BC,MATCH($A27,Tiers_list!$2:$2,0),FALSE)*('Proposal Form Tier 1'!$B$3/10)*(1-'Proposal Form Tier 1'!$B$16-'Proposal Form Tier 1'!$B$14),0) -> 0 | K27: =J27*50% -> 0 | L27: =SUM(M27:O27) -> 0 | M27: =IF($I27>0,+'Proposal Form Tier 1'!$B$8,0) -> 0 | N27: =IF($I27>0,+'Proposal Form Tier 1'!$B$9,0) -> 0 | O27: =IF($I27>0,+'Proposal Form Tier 1'!$B$10,0) -> 0 | P27: =+(J27/(1-'Proposal Form Tier 1'!$B$16-'Proposal Form Tier 1'!$B$14))+(K27/(1-'Proposal Form Tier 1'!$B$16-'Proposal Form Tier 1'!$B$14)) -> 0
A28: 200-50054 | B28: ACS Software | C28: ACS Enterprise Integrations | D28: =_xlfn.XLOOKUP(A28,Tiers_list!$2:$2,Tiers_list!$1:$1,,0) -> ACS Hardware and Facility Sensor Data Integration(s) Module | E28: Facility Sensors integrated to an ACS controller and with Third Party Hardware Data Point (ATM, NVR, Alarm system, etc.) integrations for Loitering, Light, Door, Ingress, Egress, SkimGard, etc. supervision | F28: ACS Cloud Enterprise connects facility sensors and third-party hardware devices to the ACS controller ecosystem, enabling sensor-triggered events — such as light sensor readings, presence detection, or environmental alerts — to be captured, processed, and forwarded alongside standard access control events. This gives operators a unified operational picture that combines physical security with facility intelligence, supporting use cases from loitering detection and single-access enforcement to automated alarm responses tied to environmental conditions. | G28: Optional | H28: ea. | I28: =_xlfn.XLOOKUP($A28,'Proposal Form Tier 1'!$C:$C,'Proposal Form Tier 1'!$B:$B,0,0) -> 0 | J28: =IF(I28<>0,VLOOKUP('Proposal Form Tier 1'!$B$5,Tiers_list!$A:$BC,MATCH($A28,Tiers_list!$2:$2,0),FALSE)*('Proposal Form Tier 1'!$B$3/10)*(1-'Proposal Form Tier 1'!$B$16-'Proposal Form Tier 1'!$B$14),0) -> 0 | K28: =J28*50% -> 0 | L28: =SUM(M28:O28) -> 0 | M28: =IF($I28>0,+'Proposal Form Tier 1'!$B$8,0) -> 0 | N28: =IF($I28>0,+'Proposal Form Tier 1'!$B$9,0) -> 0 | O28: =IF($I28>0,+'Proposal Form Tier 1'!$B$10,0) -> 0 | P28: =+(J28/(1-'Proposal Form Tier 1'!$B$16-'Proposal Form Tier 1'!$B$14))+(K28/(1-'Proposal Form Tier 1'!$B$16-'Proposal Form Tier 1'!$B$14)) -> 0
C29: ACS Enterprise Integrations Total | I29: =SUBTOTAL(9,I20:I28) -> 4 | J29: =SUBTOTAL(9,J20:J28) -> 548.4375 | K29: =SUBTOTAL(9,K20:K28) -> 274.21875 | L29: =SUBTOTAL(9,L20:L28) -> 4 | M29: =SUBTOTAL(9,M20:M28) -> 0 | N29: =SUBTOTAL(9,N20:N28) -> 0 | O29: =SUBTOTAL(9,O20:O28) -> 4 | P29: =SUBTOTAL(9,P20:P28) -> 1096.875
A30: 200-50055 | B30: ACS Software | C30: ACS Enterprise Hardware and Software System Supervision and Activity Logs | D30: =_xlfn.XLOOKUP(A30,Tiers_list!$2:$2,Tiers_list!$1:$1,,0) -> ACS User Data changed / functions executed Activity Tracking Module | E30: ACS User Data changed / functions executed Activity Tracking | F30: Every action taken by an ACS user — from configuration changes and schedule updates to credential assignments and system logins — is automatically captured and stored in a structured activity log that records who did what, when, and from where. Administrators and auditors can search, filter, and export these logs at any time, providing the complete chain of accountability needed for internal audits, compliance reviews, and security investigations without relying on manual record-keeping. | G30: Required | H30: ea. | I30: =+'Proposal Form Tier 1'!$B$6 -> 1 | J30: =IF(I30<>0,VLOOKUP('Proposal Form Tier 1'!$B$5,Tiers_list!$A:$BC,MATCH($A30,Tiers_list!$2:$2,0),FALSE)*('Proposal Form Tier 1'!$B$3/10)*(1-'Proposal Form Tier 1'!$B$16-'Proposal Form Tier 1'!$B$14),0) -> 126.5625 | K30: =J30*50% -> 63.28125 | L30: =SUM(M30:O30) -> 1 | M30: =IF($I30>0,+'Proposal Form Tier 1'!$B$8,0) -> 0 | N30: =IF($I30>0,+'Proposal Form Tier 1'!$B$9,0) -> 0 | O30: =IF($I30>0,+'Proposal Form Tier 1'!$B$10,0) -> 1 | P30: =+(J30/(1-'Proposal Form Tier 1'!$B$16-'Proposal Form Tier 1'!$B$14))+(K30/(1-'Proposal Form Tier 1'!$B$16-'Proposal Form Tier 1'!$B$14)) -> 253.125
A31: 200-50056 | B31: ACS Software | C31: ACS Enterprise Hardware and Software System Supervision and Activity Logs | D31: =_xlfn.XLOOKUP(A31,Tiers_list!$2:$2,Tiers_list!$1:$1,,0) -> ACS Hardware / Software availability monitoring Module | E31: Monitor ACS controller and MMR 2.0 Reader Heartbeats and software / DB availability. Event Messages when ACS hardware, MMR 2.0 readers, ACS software and DB availability are not responding to heartbeat requests | F31: ACS Cloud Enterprise continuously monitors the heartbeat signals from every controller and MMR 2.0 reader in the network, detecting offline devices within a configurable threshold and triggering immediate alerts to the responsible team before the issue impacts operations. Administrators can set monitoring intervals, configure escalation rules, view real-time device status dashboards, and access detailed uptime and connectivity reports — transforming device health monitoring from a reactive, manual process into a proactive, automated capability. | G31: Required | H31: ea. | I31: =+'Proposal Form Tier 1'!$B$6 -> 1 | J31: =IF(I31<>0,VLOOKUP('Proposal Form Tier 1'!$B$5,Tiers_list!$A:$BC,MATCH($A31,Tiers_list!$2:$2,0),FALSE)*('Proposal Form Tier 1'!$B$3/10)*(1-'Proposal Form Tier 1'!$B$16-'Proposal Form Tier 1'!$B$14),0) -> 168.75 | K31: =J31*50% -> 84.375 | L31: =SUM(M31:O31) -> 1 | M31: =IF($I31>0,+'Proposal Form Tier 1'!$B$8,0) -> 0 | N31: =IF($I31>0,+'Proposal Form Tier 1'!$B$9,0) -> 0 | O31: =IF($I31>0,+'Proposal Form Tier 1'!$B$10,0) -> 1 | P31: =+(J31/(1-'Proposal Form Tier 1'!$B$16-'Proposal Form Tier 1'!$B$14))+(K31/(1-'Proposal Form Tier 1'!$B$16-'Proposal Form Tier 1'!$B$14)) -> 337.5
A32: 200-50057 | B32: ACS Software | C32: ACS Enterprise Hardware and Software System Supervision and Activity Logs | D32: =_xlfn.XLOOKUP(A32,Tiers_list!$2:$2,Tiers_list!$1:$1,,0) -> ACS Hardware Configuration Discrepancy Supervision, Notification and Auto Correct Service Module | E32: Collect/Validate/Report/Notify of ACS hardware configuration discrepancies with configuration settings defined for each ACS / MMR 2.0 hardware device within the DB | F32: ACS Cloud Enterprise automatically compares the configuration stored in the cloud database against the actual configuration resident in each controller, flagging any discrepancies in schedules, credential lists, network settings, or device assignments before they cause operational failures or compliance gaps. When a mismatch is detected, the system notifies the responsible team and provides the context needed to resolve the discrepancy quickly — eliminating the silent configuration drift that can undermine security and audit readiness in large, distributed deployments. | G32: Required | H32: ea. | I32: =+'Proposal Form Tier 1'!$B$6 -> 1 | J32: =IF(I32<>0,VLOOKUP('Proposal Form Tier 1'!$B$5,Tiers_list!$A:$BC,MATCH($A32,Tiers_list!$2:$2,0),FALSE)*('Proposal Form Tier 1'!$B$3/10)*(1-'Proposal Form Tier 1'!$B$16-'Proposal Form Tier 1'!$B$14),0) -> 126.5625 | K32: =J32*50% -> 63.28125 | L32: =SUM(M32:O32) -> 1 | M32: =IF($I32>0,+'Proposal Form Tier 1'!$B$8,0) -> 0 | N32: =IF($I32>0,+'Proposal Form Tier 1'!$B$9,0) -> 0 | O32: =IF($I32>0,+'Proposal Form Tier 1'!$B$10,0) -> 1 | P32: =+(J32/(1-'Proposal Form Tier 1'!$B$16-'Proposal Form Tier 1'!$B$14))+(K32/(1-'Proposal Form Tier 1'!$B$16-'Proposal Form Tier 1'!$B$14)) -> 253.125
A33: 200-50058 | B33: ACS Software | C33: ACS Enterprise Hardware and Software System Supervision and Activity Logs | D33: =_xlfn.XLOOKUP(A33,Tiers_list!$2:$2,Tiers_list!$1:$1,,0) -> Suspend distribution of Select or All Event Messages generated by ACS hardware and software Module | E33: Suspend ACS hardware and software message transmission and/or integration configuration activation with an until date/time | F33: Operators can temporarily suspend the transmission of ACS event messages and integration configurations to specified external systems for a defined window — providing a controlled way to pause outbound data flows during maintenance, system updates, or planned downtime without losing the underlying event data. All suppression activity is logged, suppressed server lists are visible for audit review, and normal transmission resumes automatically when the suppression window closes, ensuring that operational maintenance never creates permanent gaps in the monitoring record. | G33: Optional | H33: ea. | I33: =_xlfn.XLOOKUP($A33,'Proposal Form Tier 1'!$C:$C,'Proposal Form Tier 1'!$B:$B,0,0) -> 0 | J33: =IF(I33<>0,VLOOKUP('Proposal Form Tier 1'!$B$5,Tiers_list!$A:$BC,MATCH($A33,Tiers_list!$2:$2,0),FALSE)*('Proposal Form Tier 1'!$B$3/10)*(1-'Proposal Form Tier 1'!$B$16-'Proposal Form Tier 1'!$B$14),0) -> 0 | K33: =J33*50% -> 0 | L33: =SUM(M33:O33) -> 0 | M33: =IF($I33>0,+'Proposal Form Tier 1'!$B$8,0) -> 0 | N33: =IF($I33>0,+'Proposal Form Tier 1'!$B$9,0) -> 0 | O33: =IF($I33>0,+'Proposal Form Tier 1'!$B$10,0) -> 0 | P33: =+(J33/(1-'Proposal Form Tier 1'!$B$16-'Proposal Form Tier 1'!$B$14))+(K33/(1-'Proposal Form Tier 1'!$B$16-'Proposal Form Tier 1'!$B$14)) -> 0
C34: ACS Enterprise Hardware and Software System Supervision and Activity Logs Total | I34: =SUBTOTAL(9,I30:I33) -> 3 | J34: =SUBTOTAL(9,J30:J33) -> 421.875 | K34: =SUBTOTAL(9,K30:K33) -> 210.9375 | L34: =SUBTOTAL(9,L30:L33) -> 3 | M34: =SUBTOTAL(9,M30:M33) -> 0 | N34: =SUBTOTAL(9,N30:N33) -> 0 | O34: =SUBTOTAL(9,O30:O33) -> 3 | P34: =SUBTOTAL(9,P30:P33) -> 843.75
A35: 200-50059 | B35: ACS Software | C35: ACS Enterprise Mass Programming and Data Collection/Receiving Services | D35: =_xlfn.XLOOKUP(A35,Tiers_list!$2:$2,Tiers_list!$1:$1,,0) -> ACS Job Scheduler Service Module | E35: ACS Users schedule effective date/time ACS controller/MMR 2.0 reader configurations to be executed, i.e., reader, I/O, 3rd party integrations, temporary override, configuration settings, weekly and holiday schedules, firmware updates, encryption key/certificate updates, data collection, etc. | F35: Administrators and operators can schedule automated jobs to push configuration updates, initialize access schedules, and manage credential lists across any number of controllers and sites at a defined date and time — eliminating the need for manual, site-by-site initialization during operational hours. Jobs can be configured for one-time, weekly, or monthly recurrence, scoped to individual sites or entire territories, and monitored in real time with automatic retry logic and failure alerts, making large-scale system updates manageable, predictable, and audit-ready. | G35: Required. Choose QTY | H35: ea. | I35: =_xlfn.XLOOKUP($A35,'Proposal Form Tier 1'!$C:$C,'Proposal Form Tier 1'!$B:$B,0,0) -> 1 | J35: =IF(I35<>0,VLOOKUP('Proposal Form Tier 1'!$B$5,Tiers_list!$A:$BC,MATCH($A35,Tiers_list!$2:$2,0),FALSE)*('Proposal Form Tier 1'!$B$3/10)*(1-'Proposal Form Tier 1'!$B$16-'Proposal Form Tier 1'!$B$14),0) -> 126.5625 | K35: =J35*50% -> 63.28125 | L35: =SUM(M35:O35) -> 1 | M35: =IF($I35>0,+'Proposal Form Tier 1'!$B$8,0) -> 0 | N35: =IF($I35>0,+'Proposal Form Tier 1'!$B$9,0) -> 0 | O35: =IF($I35>0,+'Proposal Form Tier 1'!$B$10,0) -> 1 | P35: =+(J35/(1-'Proposal Form Tier 1'!$B$16-'Proposal Form Tier 1'!$B$14))+(K35/(1-'Proposal Form Tier 1'!$B$16-'Proposal Form Tier 1'!$B$14)) -> 253.125
A36: 200-50060 | B36: ACS Software | C36: ACS Enterprise Mass Programming and Data Collection/Receiving Services | D36: =_xlfn.XLOOKUP(A36,Tiers_list!$2:$2,Tiers_list!$1:$1,,0) -> AFH / Data Collection Service Module | E36: Collect/receive ACS hardware / software status Event Messages, Credential Events, User activity and writes stores them within the ACS SQL DB. | F36: ACS Cloud Enterprise continuously collects and stores every event message and credential read event transmitted by ACS controllers in real time — covering access grants, rejections, alarms, device status updates, login events, and more — into a centralized, searchable audit trail. Operators can view, filter, and export this complete event history at any time, ensuring that the full record of what happened at every entrance, on every device, across every site is always available for security review, incident investigation, or compliance reporting. | G36: Required. Choose Qty | H36: ea. | I36: =_xlfn.XLOOKUP($A36,'Proposal Form Tier 1'!$C:$C,'Proposal Form Tier 1'!$B:$B,0,0) -> 1 | J36: =IF(I36<>0,VLOOKUP('Proposal Form Tier 1'!$B$5,Tiers_list!$A:$BC,MATCH($A36,Tiers_list!$2:$2,0),FALSE)*('Proposal Form Tier 1'!$B$3/10)*(1-'Proposal Form Tier 1'!$B$16-'Proposal Form Tier 1'!$B$14),0) -> 126.5625 | K36: =J36*50% -> 63.28125 | L36: =SUM(M36:O36) -> 1 | M36: =IF($I36>0,+'Proposal Form Tier 1'!$B$8,0) -> 0 | N36: =IF($I36>0,+'Proposal Form Tier 1'!$B$9,0) -> 0 | O36: =IF($I36>0,+'Proposal Form Tier 1'!$B$10,0) -> 1 | P36: =+(J36/(1-'Proposal Form Tier 1'!$B$16-'Proposal Form Tier 1'!$B$14))+(K36/(1-'Proposal Form Tier 1'!$B$16-'Proposal Form Tier 1'!$B$14)) -> 253.125
A37: 200-50061 | B37: ACS Software | C37: ACS Enterprise Mass Programming and Data Collection/Receiving Services | D37: =_xlfn.XLOOKUP(A37,Tiers_list!$2:$2,Tiers_list!$1:$1,,0) -> Remote ACS Hardware firmware updates Module | E37: Remote ACS controller and MMR 2.0 reader firmware updates | F37: Administrators can remotely update the firmware of ACS controllers and MMR 2.0 readers across all sites without dispatching technicians — selecting the target firmware version, scoping the update to specific devices or territories, and scheduling execution during off-peak hours through the job scheduler. Firmware files go through an approval process before deployment, update progress is tracked in real time with automatic retry on failure, and all activity is logged — ensuring that every device in the estate stays current, secure, and operating on validated software. | G37: Required. Choose Qty | H37: ea. | I37: =_xlfn.XLOOKUP($A37,'Proposal Form Tier 1'!$C:$C,'Proposal Form Tier 1'!$B:$B,0,0) -> 1 | J37: =IF(I37<>0,VLOOKUP('Proposal Form Tier 1'!$B$5,Tiers_list!$A:$BC,MATCH($A37,Tiers_list!$2:$2,0),FALSE)*('Proposal Form Tier 1'!$B$3/10)*(1-'Proposal Form Tier 1'!$B$16-'Proposal Form Tier 1'!$B$14),0) -> 168.75 | K37: =J37*50% -> 84.375 | L37: =SUM(M37:O37) -> 1 | M37: =IF($I37>0,+'Proposal Form Tier 1'!$B$8,0) -> 0 | N37: =IF($I37>0,+'Proposal Form Tier 1'!$B$9,0) -> 0 | O37: =IF($I37>0,+'Proposal Form Tier 1'!$B$10,0) -> 1 | P37: =+(J37/(1-'Proposal Form Tier 1'!$B$16-'Proposal Form Tier 1'!$B$14))+(K37/(1-'Proposal Form Tier 1'!$B$16-'Proposal Form Tier 1'!$B$14)) -> 337.5
A38: 200-50062 | B38: ACS Software | C38: ACS Enterprise Mass Programming and Data Collection/Receiving Services | D38: =_xlfn.XLOOKUP(A38,Tiers_list!$2:$2,Tiers_list!$1:$1,,0) -> Door / Entrance Supervision Configuration Module | E38: Configuration of Door Ajar, Door Opening Excessively during Access and Locked scheduled states. Event message thresholds are configurable for entry and egress supervision frequency.(Requires a Door Contact and Egress device integrated into the ACS controller) | F38: Operators can configure and enforce door behavior rules that detect when a door is left open beyond an acceptable time (Door Ajar) or opened too frequently relative to credential reads — triggering alerts before a minor door issue becomes a security or compliance concern. Threshold values are configurable per reader and per site, default settings can be applied organization-wide, and all configuration changes are logged with full traceability of who set what and when. | G38: Optional | H38: ea. | I38: =_xlfn.XLOOKUP($A38,'Proposal Form Tier 1'!$C:$C,'Proposal Form Tier 1'!$B:$B,0,0) -> 0 | J38: =IF(I38<>0,VLOOKUP('Proposal Form Tier 1'!$B$5,Tiers_list!$A:$BC,MATCH($A38,Tiers_list!$2:$2,0),FALSE)*('Proposal Form Tier 1'!$B$3/10)*(1-'Proposal Form Tier 1'!$B$16-'Proposal Form Tier 1'!$B$14),0) -> 0 | K38: =J38*50% -> 0 | L38: =SUM(M38:O38) -> 0 | M38: =IF($I38>0,+'Proposal Form Tier 1'!$B$8,0) -> 0 | N38: =IF($I38>0,+'Proposal Form Tier 1'!$B$9,0) -> 0 | O38: =IF($I38>0,+'Proposal Form Tier 1'!$B$10,0) -> 0 | P38: =+(J38/(1-'Proposal Form Tier 1'!$B$16-'Proposal Form Tier 1'!$B$14))+(K38/(1-'Proposal Form Tier 1'!$B$16-'Proposal Form Tier 1'!$B$14)) -> 0
A39: 200-50063 | B39: ACS Software | C39: ACS Enterprise Mass Programming and Data Collection/Receiving Services | D39: =_xlfn.XLOOKUP(A39,Tiers_list!$2:$2,Tiers_list!$1:$1,,0) -> ACS Hardware Firmware Version Supervision Module | E39: MMR 2.0 reader and ACS controller approved firmware version and serial number supervision | F39: ACS Cloud Enterprise maintains a live inventory of the approved firmware versions and serial numbers for every controller and reader in the estate, automatically flagging devices that are running outdated or unapproved firmware versions. This gives administrators a continuous, accurate view of firmware compliance across the entire device fleet, supports proactive update planning, and ensures that no device is overlooked during firmware rollouts — eliminating the audit risk of unknown or uncertified firmware running in a live security environment. | G39: Required | H39: ea. | I39: =+'Proposal Form Tier 1'!$B$6 -> 1 | J39: =IF(I39<>0,VLOOKUP('Proposal Form Tier 1'!$B$5,Tiers_list!$A:$BC,MATCH($A39,Tiers_list!$2:$2,0),FALSE)*('Proposal Form Tier 1'!$B$3/10)*(1-'Proposal Form Tier 1'!$B$16-'Proposal Form Tier 1'!$B$14),0) -> 84.375 | K39: =J39*50% -> 42.1875 | L39: =SUM(M39:O39) -> 1 | M39: =IF($I39>0,+'Proposal Form Tier 1'!$B$8,0) -> 0 | N39: =IF($I39>0,+'Proposal Form Tier 1'!$B$9,0) -> 0 | O39: =IF($I39>0,+'Proposal Form Tier 1'!$B$10,0) -> 1 | P39: =+(J39/(1-'Proposal Form Tier 1'!$B$16-'Proposal Form Tier 1'!$B$14))+(K39/(1-'Proposal Form Tier 1'!$B$16-'Proposal Form Tier 1'!$B$14)) -> 168.75
A40: 200-50064 | B40: ACS Software | C40: ACS Enterprise Mass Programming and Data Collection/Receiving Services | D40: =_xlfn.XLOOKUP(A40,Tiers_list!$2:$2,Tiers_list!$1:$1,,0) -> ACS Data Retention / Archive Module | E40: Definable ACS data (Credentials read, Event Message, ACS User Activity and hardware configuration history) archive management, reports and archive data history viewer. | F40: ACS Cloud Enterprise enables administrators to define retention policies for all system data — including credential events, configuration history, user activity logs, and hardware records — with automatic archiving and purging that keeps storage costs under control while ensuring the organization meets its regulatory and compliance obligations. Archived data remains accessible during the retention window, all archiving activity is captured in a compliance audit log, and access to archived records is restricted to authorized personnel — giving organizations defensible data governance without manual data management overhead. | G40: Required | H40: ea. | I40: =+'Proposal Form Tier 1'!$B$6 -> 1 | J40: =IF(I40<>0,VLOOKUP('Proposal Form Tier 1'!$B$5,Tiers_list!$A:$BC,MATCH($A40,Tiers_list!$2:$2,0),FALSE)*('Proposal Form Tier 1'!$B$3/10)*(1-'Proposal Form Tier 1'!$B$16-'Proposal Form Tier 1'!$B$14),0) -> 84.375 | K40: =J40*50% -> 42.1875 | L40: =SUM(M40:O40) -> 1 | M40: =IF($I40>0,+'Proposal Form Tier 1'!$B$8,0) -> 0 | N40: =IF($I40>0,+'Proposal Form Tier 1'!$B$9,0) -> 0 | O40: =IF($I40>0,+'Proposal Form Tier 1'!$B$10,0) -> 1 | P40: =+(J40/(1-'Proposal Form Tier 1'!$B$16-'Proposal Form Tier 1'!$B$14))+(K40/(1-'Proposal Form Tier 1'!$B$16-'Proposal Form Tier 1'!$B$14)) -> 168.75
...

Sheet Proposal Summary - Tier 1
A1: =CONCATENATE("Confidential Parabit Private-Public Cloud On-Premise ACS Enterprise Tiered Software Quote for ",'Proposal Form Tier 2-12'!B2) -> Confidential Parabit Private-Public Cloud On-Premise ACS Enterprise Tiered Software Quote for Bank of America
A2: New ACS Private/Public Cloud and On-Prem Enterprise software suite Annual License Fees
A3: See detail price list for a breakdown of each line items pricing
F4: Integrator | G4: End User
F5: =+'Proposal Form Tier 1'!B15 -> Securitas Technology Co. | G5: =+'Proposal Form Tier 1'!B2 -> Bank of America
A6: Annual and One-Time New ACS Enterprise Private Cloud/Parabit ACSaaS/On-Prem Software Features and Professional Services | B6: =+'Detail_Proposal_tier 1'!I1 -> Tier - 1 - 10 Quantity of Primary Production Instance(s) | C6: =+'Detail_Proposal_tier 1'!J1 -> Tier - 1 - 10 Total Annual Primary Instance(s) Pricing | D6: =+'Detail_Proposal_tier 1'!K1 -> Tier - 1 - 10 Total Annual Fail-Over/DR Instance(s) Pricing | E6: =+'Detail_Proposal_tier 1'!L1 -> Tier - 1 - 10 Total Quantity of Annual Fail-Over/DR Instance(s) | F6: =+'Proposal Summary - Tier 2-12'!F6 -> Total Price | G6: =+'Proposal Summary - Tier 2-12'!G6 -> MSRP / Tier Price Total
A7: =+'Proposal Summary - Tier 2-12'!A7 -> ACS Enterprise Hardware Configuration UI | B7: =SUMIF('Detail_Proposal_tier 1'!$C:$L,$A7,'Detail_Proposal_tier 1'!I:I) -> 3 | C7: =SUMIF('Detail_Proposal_tier 1'!$C:$L,$A7,'Detail_Proposal_tier 1'!J:J) -> 2278.125 | D7: =SUMIF('Detail_Proposal_tier 1'!$C:$L,$A7,'Detail_Proposal_tier 1'!L:L) -> 3 | E7: =SUMIF('Detail_Proposal_tier 1'!$C:$L,$A7,'Detail_Proposal_tier 1'!K:K) -> 1139.0625 | F7: =+E7+C7 -> 3417.1875 | G7: =SUMIF('Detail_Proposal_tier 1'!$C:$L,$A7,'Detail_Proposal_tier 1'!P:P) -> 4556.25
A8: =+'Proposal Summary - Tier 2-12'!A8 -> ACS Enterprise Integrations | B8: =SUMIF('Detail_Proposal_tier 1'!$C:$L,$A8,'Detail_Proposal_tier 1'!I:I) -> 4 | C8: =SUMIF('Detail_Proposal_tier 1'!$C:$L,$A8,'Detail_Proposal_tier 1'!J:J) -> 548.4375 | D8: =SUMIF('Detail_Proposal_tier 1'!$C:$L,$A8,'Detail_Proposal_tier 1'!L:L) -> 4 | E8: =SUMIF('Detail_Proposal_tier 1'!$C:$L,$A8,'Detail_Proposal_tier 1'!K:K) -> 274.21875 | F8: =+E8+C8 -> 822.65625 | G8: =SUMIF('Detail_Proposal_tier 1'!$C:$L,$A8,'Detail_Proposal_tier 1'!P:P) -> 1096.875
A9: =+'Proposal Summary - Tier 2-12'!A9 -> ACS Enterprise Hardware and Software System Supervision and Activity Logs | B9: =SUMIF('Detail_Proposal_tier 1'!$C:$L,$A9,'Detail_Proposal_tier 1'!I:I) -> 3 | C9: =SUMIF('Detail_Proposal_tier 1'!$C:$L,$A9,'Detail_Proposal_tier 1'!J:J) -> 421.875 | D9: =SUMIF('Detail_Proposal_tier 1'!$C:$L,$A9,'Detail_Proposal_tier 1'!L:L) -> 3 | E9: =SUMIF('Detail_Proposal_tier 1'!$C:$L,$A9,'Detail_Proposal_tier 1'!K:K) -> 210.9375 | F9: =+E9+C9 -> 632.8125 | G9: =SUMIF('Detail_Proposal_tier 1'!$C:$L,$A9,'Detail_Proposal_tier 1'!P:P) -> 843.75
A10: =+'Proposal Summary - Tier 2-12'!A10 -> ACS Enterprise Mass Programming and Data Collection/Receiving Services | B10: =SUMIF('Detail_Proposal_tier 1'!$C:$L,$A10,'Detail_Proposal_tier 1'!I:I) -> 7 | C10: =SUMIF('Detail_Proposal_tier 1'!$C:$L,$A10,'Detail_Proposal_tier 1'!J:J) -> 801.5625 | D10: =SUMIF('Detail_Proposal_tier 1'!$C:$L,$A10,'Detail_Proposal_tier 1'!L:L) -> 7 | E10: =SUMIF('Detail_Proposal_tier 1'!$C:$L,$A10,'Detail_Proposal_tier 1'!K:K) -> 400.78125 | F10: =+E10+C10 -> 1202.3438 | G10: =SUMIF('Detail_Proposal_tier 1'!$C:$L,$A10,'Detail_Proposal_tier 1'!P:P) -> 1603.125
A11: =+'Proposal Summary - Tier 2-12'!A11 -> Annual ACS Cloud Enterprise Ecosystem, Hardware, Facility Sensors, Reader Monitoring UI features | B11: =SUMIF('Detail_Proposal_tier 1'!$C:$L,$A11,'Detail_Proposal_tier 1'!I:I) -> 2 | C11: =SUMIF('Detail_Proposal_tier 1'!$C:$L,$A11,'Detail_Proposal_tier 1'!J:J) -> 210.9375 | D11: =SUMIF('Detail_Proposal_tier 1'!$C:$L,$A11,'Detail_Proposal_tier 1'!L:L) -> 2 | E11: =SUMIF('Detail_Proposal_tier 1'!$C:$L,$A11,'Detail_Proposal_tier 1'!K:K) -> 105.46875 | F11: =+E11+C11 -> 316.40625 | G11: =SUMIF('Detail_Proposal_tier 1'!$C:$L,$A11,'Detail_Proposal_tier 1'!P:P) -> 421.875
